2023-03-01 17:09:07,810 INFO    MainThread:10612 [wandb_setup.py:_flush():68] Configure stats pid to 10612
2023-03-01 17:09:07,811 INFO    MainThread:10612 [wandb_setup.py:_flush():68] Loading settings from /home/daniel/.config/wandb/settings
2023-03-01 17:09:07,811 INFO    MainThread:10612 [wandb_setup.py:_flush():68] Loading settings from /home/daniel/DARM/darm_mujoco/darm_training/wandb/settings
2023-03-01 17:09:07,811 INFO    MainThread:10612 [wandb_setup.py:_flush():68] Loading settings from environment variables: {'_require_service': 'True'}
2023-03-01 17:09:07,811 INFO    MainThread:10612 [wandb_setup.py:_flush():68] Inferring run settings from compute environment: {'program': '<python with no main file>'}
2023-03-01 17:09:07,811 INFO    MainThread:10612 [wandb_init.py:_log_setup():492] Logging user logs to /home/daniel/DARM/darm_mujoco/darm_training/wandb/run-20230301_170907-wf7bthr5/logs/debug.log
2023-03-01 17:09:07,812 INFO    MainThread:10612 [wandb_init.py:_log_setup():493] Logging internal logs to /home/daniel/DARM/darm_mujoco/darm_training/wandb/run-20230301_170907-wf7bthr5/logs/debug-internal.log
2023-03-01 17:09:07,812 INFO    MainThread:10612 [wandb_init.py:_jupyter_setup():438] configuring jupyter hooks <wandb.sdk.wandb_init._WandbInit object at 0x7f3a540777f0>
2023-03-01 17:09:07,813 INFO    MainThread:10612 [wandb_init.py:init():532] calling init triggers
2023-03-01 17:09:07,814 INFO    MainThread:10612 [wandb_init.py:init():538] wandb.init called with sweep_config: {}
config: {'env_id': 'darm/DarmHand-v0', 'single_finger_env': False, 'algo': 'SAC', 'rl_lib': 'SB3', 'seed': 0, 'mean_reward_thresh': 1300, 'total_timesteps': 10000000, 'pi_net_arch': [128, 256, 256, 128], 'qf_net_arch': [128, 256, 256, 128], 'learning_starts': 40000, 'num_cpu': 6, 'eval_freq': 2000, 'max_no_improvement_evals': 10, 'no_improvement_min_evals': 20, 'log_interval': 20, 'wandb_model_save_freq': 2000, 'run_local_dir': '/home/daniel/DARM/darm_mujoco/darm_training/results/darm_mf_hand/test1_MF_SB3_SAC'}
2023-03-01 17:09:07,814 INFO    MainThread:10612 [wandb_init.py:init():588] starting backend
2023-03-01 17:09:07,814 INFO    MainThread:10612 [wandb_init.py:init():592] setting up manager
2023-03-01 17:09:07,818 INFO    MainThread:10612 [backend.py:_multiprocessing_setup():106] multiprocessing start_methods=fork,spawn,forkserver, using: spawn
2023-03-01 17:09:07,823 INFO    MainThread:10612 [wandb_init.py:init():599] backend started and connected
2023-03-01 17:09:07,829 INFO    MainThread:10612 [wandb_run.py:_label_probe_notebook():1203] probe notebook
2023-03-01 17:09:07,830 INFO    MainThread:10612 [wandb_run.py:_label_probe_notebook():1213] Unable to probe notebook: 'NoneType' object has no attribute 'get'
2023-03-01 17:09:07,830 INFO    MainThread:10612 [wandb_init.py:init():687] updated telemetry
2023-03-01 17:09:07,914 INFO    MainThread:10612 [wandb_init.py:init():727] communicating run to backend with 60.0 second timeout
2023-03-01 17:09:11,899 WARNING MainThread:10612 [wandb_init.py:init():1154] interrupted
Traceback (most recent call last):
  File "/home/daniel/miniconda3/lib/python3.8/site-packages/wandb/sdk/wandb_init.py", line 1133, in init
    run = wi.init()
  File "/home/daniel/miniconda3/lib/python3.8/site-packages/wandb/sdk/wandb_init.py", line 730, in init
    result = run_init_handle.wait(
  File "/home/daniel/miniconda3/lib/python3.8/site-packages/wandb/sdk/lib/mailbox.py", line 273, in wait
    found, abandoned = self._slot._get_and_clear(timeout=wait_timeout)
  File "/home/daniel/miniconda3/lib/python3.8/site-packages/wandb/sdk/lib/mailbox.py", line 120, in _get_and_clear
    if self._wait(timeout=timeout):
  File "/home/daniel/miniconda3/lib/python3.8/site-packages/wandb/sdk/lib/mailbox.py", line 116, in _wait
    return self._event.wait(timeout=timeout)
  File "/home/daniel/miniconda3/lib/python3.8/threading.py", line 558, in wait
    signaled = self._cond.wait(timeout)
  File "/home/daniel/miniconda3/lib/python3.8/threading.py", line 306, in wait
    gotit = waiter.acquire(True, timeout)
KeyboardInterrupt
2023-03-01 17:09:36,214 INFO    Thread-4  :10612 [retry.py:__call__():172] Retry attempt failed:
Traceback (most recent call last):
  File "/home/daniel/miniconda3/lib/python3.8/site-packages/urllib3/connectionpool.py", line 386, in _make_request
    self._validate_conn(conn)
  File "/home/daniel/miniconda3/lib/python3.8/site-packages/urllib3/connectionpool.py", line 1042, in _validate_conn
    conn.connect()
  File "/home/daniel/miniconda3/lib/python3.8/site-packages/urllib3/connection.py", line 414, in connect
    self.sock = ssl_wrap_socket(
  File "/home/daniel/miniconda3/lib/python3.8/site-packages/urllib3/util/ssl_.py", line 449, in ssl_wrap_socket
    ssl_sock = _ssl_wrap_socket_impl(
  File "/home/daniel/miniconda3/lib/python3.8/site-packages/urllib3/util/ssl_.py", line 493, in _ssl_wrap_socket_impl
    return ssl_context.wrap_socket(sock, server_hostname=server_hostname)
  File "/home/daniel/miniconda3/lib/python3.8/ssl.py", line 500, in wrap_socket
    return self.sslsocket_class._create(
  File "/home/daniel/miniconda3/lib/python3.8/ssl.py", line 1040, in _create
    self.do_handshake()
  File "/home/daniel/miniconda3/lib/python3.8/ssl.py", line 1309, in do_handshake
    self._sslobj.do_handshake()
socket.timeout: _ssl.c:1114: The handshake operation timed out

During handling of the above exception, another exception occurred:

Traceback (most recent call last):
  File "/home/daniel/miniconda3/lib/python3.8/site-packages/requests/adapters.py", line 440, in send
    resp = conn.urlopen(
  File "/home/daniel/miniconda3/lib/python3.8/site-packages/urllib3/connectionpool.py", line 787, in urlopen
    retries = retries.increment(
  File "/home/daniel/miniconda3/lib/python3.8/site-packages/urllib3/util/retry.py", line 550, in increment
    raise six.reraise(type(error), error, _stacktrace)
  File "/home/daniel/miniconda3/lib/python3.8/site-packages/urllib3/packages/six.py", line 770, in reraise
    raise value
  File "/home/daniel/miniconda3/lib/python3.8/site-packages/urllib3/connectionpool.py", line 703, in urlopen
    httplib_response = self._make_request(
  File "/home/daniel/miniconda3/lib/python3.8/site-packages/urllib3/connectionpool.py", line 389, in _make_request
    self._raise_timeout(err=e, url=url, timeout_value=conn.timeout)
  File "/home/daniel/miniconda3/lib/python3.8/site-packages/urllib3/connectionpool.py", line 340, in _raise_timeout
    raise ReadTimeoutError(
urllib3.exceptions.ReadTimeoutError: HTTPSConnectionPool(host='api.wandb.ai', port=443): Read timed out. (read timeout=10)

During handling of the above exception, another exception occurred:

Traceback (most recent call last):
  File "/home/daniel/miniconda3/lib/python3.8/site-packages/wandb/sdk/lib/retry.py", line 131, in __call__
    result = self._call_fn(*args, **kwargs)
  File "/home/daniel/miniconda3/lib/python3.8/site-packages/wandb/sdk/internal/internal_api.py", line 242, in execute
    return self.client.execute(*args, **kwargs)  # type: ignore
  File "/home/daniel/miniconda3/lib/python3.8/site-packages/wandb/vendor/gql-0.2.0/wandb_gql/client.py", line 52, in execute
    result = self._get_result(document, *args, **kwargs)
  File "/home/daniel/miniconda3/lib/python3.8/site-packages/wandb/vendor/gql-0.2.0/wandb_gql/client.py", line 60, in _get_result
    return self.transport.execute(document, *args, **kwargs)
  File "/home/daniel/miniconda3/lib/python3.8/site-packages/wandb/vendor/gql-0.2.0/wandb_gql/transport/requests.py", line 38, in execute
    request = requests.post(self.url, **post_args)
  File "/home/daniel/miniconda3/lib/python3.8/site-packages/requests/api.py", line 117, in post
    return request('post', url, data=data, json=json, **kwargs)
  File "/home/daniel/miniconda3/lib/python3.8/site-packages/requests/api.py", line 61, in request
    return session.request(method=method, url=url, **kwargs)
  File "/home/daniel/miniconda3/lib/python3.8/site-packages/requests/sessions.py", line 529, in request
    resp = self.send(prep, **send_kwargs)
  File "/home/daniel/miniconda3/lib/python3.8/site-packages/requests/sessions.py", line 645, in send
    r = adapter.send(request, **kwargs)
  File "/home/daniel/miniconda3/lib/python3.8/site-packages/requests/adapters.py", line 532, in send
    raise ReadTimeout(e, request=request)
requests.exceptions.ReadTimeout: HTTPSConnectionPool(host='api.wandb.ai', port=443): Read timed out. (read timeout=10)
2023-03-01 17:28:26,817 INFO    MainThread:10612 [wandb_setup.py:_flush():68] Configure stats pid to 10612
2023-03-01 17:28:26,818 INFO    MainThread:10612 [wandb_setup.py:_flush():68] Loading settings from /home/daniel/.config/wandb/settings
2023-03-01 17:28:26,818 INFO    MainThread:10612 [wandb_setup.py:_flush():68] Loading settings from /home/daniel/DARM/darm_mujoco/darm_training/wandb/settings
2023-03-01 17:28:26,818 INFO    MainThread:10612 [wandb_setup.py:_flush():68] Loading settings from environment variables: {'_require_service': 'True'}
2023-03-01 17:28:26,819 INFO    MainThread:10612 [wandb_setup.py:_flush():68] Inferring run settings from compute environment: {'program': '<python with no main file>'}
2023-03-01 17:28:26,819 INFO    MainThread:10612 [wandb_init.py:_log_setup():492] Logging user logs to /home/daniel/DARM/darm_mujoco/darm_training/wandb/run-20230301_172826-4lvrnkpa/logs/debug.log
2023-03-01 17:28:26,819 INFO    MainThread:10612 [wandb_init.py:_log_setup():493] Logging internal logs to /home/daniel/DARM/darm_mujoco/darm_training/wandb/run-20230301_172826-4lvrnkpa/logs/debug-internal.log
2023-03-01 17:28:26,819 INFO    MainThread:10612 [wandb_init.py:init():532] calling init triggers
2023-03-01 17:28:26,820 INFO    MainThread:10612 [wandb_init.py:init():538] wandb.init called with sweep_config: {}
config: {'env_id': 'darm/DarmHand-v0', 'single_finger_env': False, 'algo': 'SAC', 'rl_lib': 'SB3', 'seed': 0, 'mean_reward_thresh': 1300, 'total_timesteps': 10000000, 'pi_net_arch': [128, 256, 256, 128], 'qf_net_arch': [128, 256, 256, 128], 'learning_starts': 40000, 'num_cpu': 6, 'eval_freq': 2000, 'max_no_improvement_evals': 10, 'no_improvement_min_evals': 20, 'log_interval': 20, 'wandb_model_save_freq': 2000, 'run_local_dir': '/home/daniel/DARM/darm_mujoco/darm_training/results/darm_mf_hand/test1_MF_SB3_SAC'}
2023-03-01 17:28:26,820 INFO    MainThread:10612 [wandb_init.py:init():588] starting backend
2023-03-01 17:28:26,820 INFO    MainThread:10612 [wandb_init.py:init():592] setting up manager
2023-03-01 17:28:26,830 INFO    MainThread:10612 [backend.py:_multiprocessing_setup():106] multiprocessing start_methods=fork,spawn,forkserver, using: spawn
2023-03-01 17:28:26,833 INFO    MainThread:10612 [wandb_init.py:init():599] backend started and connected
2023-03-01 17:28:26,839 INFO    MainThread:10612 [wandb_run.py:_label_probe_notebook():1203] probe notebook
2023-03-01 17:28:26,840 INFO    MainThread:10612 [wandb_run.py:_label_probe_notebook():1213] Unable to probe notebook: 'NoneType' object has no attribute 'get'
2023-03-01 17:28:26,840 INFO    MainThread:10612 [wandb_init.py:init():687] updated telemetry
2023-03-01 17:28:26,881 INFO    MainThread:10612 [wandb_init.py:init():727] communicating run to backend with 60.0 second timeout
2023-03-01 17:28:51,924 WARNING MainThread:10612 [wandb_init.py:init():1154] interrupted
Traceback (most recent call last):
  File "/home/daniel/miniconda3/lib/python3.8/site-packages/wandb/sdk/wandb_init.py", line 1133, in init
    run = wi.init()
  File "/home/daniel/miniconda3/lib/python3.8/site-packages/wandb/sdk/wandb_init.py", line 730, in init
    result = run_init_handle.wait(
  File "/home/daniel/miniconda3/lib/python3.8/site-packages/wandb/sdk/lib/mailbox.py", line 273, in wait
    found, abandoned = self._slot._get_and_clear(timeout=wait_timeout)
  File "/home/daniel/miniconda3/lib/python3.8/site-packages/wandb/sdk/lib/mailbox.py", line 120, in _get_and_clear
    if self._wait(timeout=timeout):
  File "/home/daniel/miniconda3/lib/python3.8/site-packages/wandb/sdk/lib/mailbox.py", line 116, in _wait
    return self._event.wait(timeout=timeout)
  File "/home/daniel/miniconda3/lib/python3.8/threading.py", line 558, in wait
    signaled = self._cond.wait(timeout)
  File "/home/daniel/miniconda3/lib/python3.8/threading.py", line 306, in wait
    gotit = waiter.acquire(True, timeout)
KeyboardInterrupt
