2023-03-01 17:09:07,827 INFO    StreamThr :10945 [internal.py:wandb_internal():87] W&B internal server running at pid: 10945, started at: 2023-03-01 17:09:07.826596
2023-03-01 17:09:07,842 DEBUG   HandlerThread:10945 [handler.py:handle_request():144] handle_request: status
2023-03-01 17:09:07,848 INFO    WriterThread:10945 [datastore.py:open_for_write():85] open: /home/daniel/DARM/darm_mujoco/darm_training/wandb/run-20230301_170907-wf7bthr5/run-wf7bthr5.wandb
2023-03-01 17:09:07,852 DEBUG   SenderThread:10945 [sender.py:send():336] send: header
2023-03-01 17:09:07,917 DEBUG   SenderThread:10945 [sender.py:send():336] send: run
2023-03-01 17:09:42,594 INFO    SenderThread:10945 [retry.py:__call__():172] Retry attempt failed:
Traceback (most recent call last):
  File "/home/daniel/miniconda3/lib/python3.8/site-packages/urllib3/connectionpool.py", line 386, in _make_request
    self._validate_conn(conn)
  File "/home/daniel/miniconda3/lib/python3.8/site-packages/urllib3/connectionpool.py", line 1042, in _validate_conn
    conn.connect()
  File "/home/daniel/miniconda3/lib/python3.8/site-packages/urllib3/connection.py", line 414, in connect
    self.sock = ssl_wrap_socket(
  File "/home/daniel/miniconda3/lib/python3.8/site-packages/urllib3/util/ssl_.py", line 449, in ssl_wrap_socket
    ssl_sock = _ssl_wrap_socket_impl(
  File "/home/daniel/miniconda3/lib/python3.8/site-packages/urllib3/util/ssl_.py", line 493, in _ssl_wrap_socket_impl
    return ssl_context.wrap_socket(sock, server_hostname=server_hostname)
  File "/home/daniel/miniconda3/lib/python3.8/ssl.py", line 500, in wrap_socket
    return self.sslsocket_class._create(
  File "/home/daniel/miniconda3/lib/python3.8/ssl.py", line 1040, in _create
    self.do_handshake()
  File "/home/daniel/miniconda3/lib/python3.8/ssl.py", line 1309, in do_handshake
    self._sslobj.do_handshake()
socket.timeout: _ssl.c:1114: The handshake operation timed out

During handling of the above exception, another exception occurred:

Traceback (most recent call last):
  File "/home/daniel/miniconda3/lib/python3.8/site-packages/requests/adapters.py", line 440, in send
    resp = conn.urlopen(
  File "/home/daniel/miniconda3/lib/python3.8/site-packages/urllib3/connectionpool.py", line 787, in urlopen
    retries = retries.increment(
  File "/home/daniel/miniconda3/lib/python3.8/site-packages/urllib3/util/retry.py", line 550, in increment
    raise six.reraise(type(error), error, _stacktrace)
  File "/home/daniel/miniconda3/lib/python3.8/site-packages/urllib3/packages/six.py", line 770, in reraise
    raise value
  File "/home/daniel/miniconda3/lib/python3.8/site-packages/urllib3/connectionpool.py", line 703, in urlopen
    httplib_response = self._make_request(
  File "/home/daniel/miniconda3/lib/python3.8/site-packages/urllib3/connectionpool.py", line 389, in _make_request
    self._raise_timeout(err=e, url=url, timeout_value=conn.timeout)
  File "/home/daniel/miniconda3/lib/python3.8/site-packages/urllib3/connectionpool.py", line 340, in _raise_timeout
    raise ReadTimeoutError(
urllib3.exceptions.ReadTimeoutError: HTTPSConnectionPool(host='api.wandb.ai', port=443): Read timed out. (read timeout=10)

During handling of the above exception, another exception occurred:

Traceback (most recent call last):
  File "/home/daniel/miniconda3/lib/python3.8/site-packages/wandb/sdk/lib/retry.py", line 131, in __call__
    result = self._call_fn(*args, **kwargs)
  File "/home/daniel/miniconda3/lib/python3.8/site-packages/wandb/sdk/internal/internal_api.py", line 242, in execute
    return self.client.execute(*args, **kwargs)  # type: ignore
  File "/home/daniel/miniconda3/lib/python3.8/site-packages/wandb/vendor/gql-0.2.0/wandb_gql/client.py", line 52, in execute
    result = self._get_result(document, *args, **kwargs)
  File "/home/daniel/miniconda3/lib/python3.8/site-packages/wandb/vendor/gql-0.2.0/wandb_gql/client.py", line 60, in _get_result
    return self.transport.execute(document, *args, **kwargs)
  File "/home/daniel/miniconda3/lib/python3.8/site-packages/wandb/vendor/gql-0.2.0/wandb_gql/transport/requests.py", line 38, in execute
    request = requests.post(self.url, **post_args)
  File "/home/daniel/miniconda3/lib/python3.8/site-packages/requests/api.py", line 117, in post
    return request('post', url, data=data, json=json, **kwargs)
  File "/home/daniel/miniconda3/lib/python3.8/site-packages/requests/api.py", line 61, in request
    return session.request(method=method, url=url, **kwargs)
  File "/home/daniel/miniconda3/lib/python3.8/site-packages/requests/sessions.py", line 529, in request
    resp = self.send(prep, **send_kwargs)
  File "/home/daniel/miniconda3/lib/python3.8/site-packages/requests/sessions.py", line 645, in send
    r = adapter.send(request, **kwargs)
  File "/home/daniel/miniconda3/lib/python3.8/site-packages/requests/adapters.py", line 532, in send
    raise ReadTimeout(e, request=request)
requests.exceptions.ReadTimeout: HTTPSConnectionPool(host='api.wandb.ai', port=443): Read timed out. (read timeout=10)
2023-03-01 17:28:26,843 INFO    StreamThr :10945 [internal.py:wandb_internal():87] W&B internal server running at pid: 10945, started at: 2023-03-01 17:28:26.840533
2023-03-01 17:28:26,849 DEBUG   HandlerThread:10945 [handler.py:handle_request():144] handle_request: status
2023-03-01 17:28:26,853 INFO    WriterThread:10945 [datastore.py:open_for_write():85] open: /home/daniel/DARM/darm_mujoco/darm_training/wandb/run-20230301_172826-4lvrnkpa/run-4lvrnkpa.wandb
2023-03-01 17:28:26,854 DEBUG   SenderThread:10945 [sender.py:send():336] send: header
2023-03-01 17:28:26,884 DEBUG   SenderThread:10945 [sender.py:send():336] send: run
2023-03-01 17:28:31,885 DEBUG   HandlerThread:10945 [handler.py:handle_request():144] handle_request: keepalive
2023-03-01 17:28:35,935 INFO    SenderThread:10945 [dir_watcher.py:__init__():216] watching files in: /home/daniel/DARM/darm_mujoco/darm_training/wandb/run-20230301_172826-4lvrnkpa/files
2023-03-01 17:28:35,935 INFO    SenderThread:10945 [sender.py:_start_run_threads():1067] run started: 4lvrnkpa with start time 1677688106.835837
2023-03-01 17:28:35,936 DEBUG   HandlerThread:10945 [handler.py:handle_request():144] handle_request: status_report
2023-03-01 17:28:36,886 DEBUG   HandlerThread:10945 [handler.py:handle_request():144] handle_request: keepalive
2023-03-01 17:28:40,938 DEBUG   HandlerThread:10945 [handler.py:handle_request():144] handle_request: status_report
2023-03-01 17:28:41,888 DEBUG   HandlerThread:10945 [handler.py:handle_request():144] handle_request: keepalive
2023-03-01 17:28:45,939 DEBUG   HandlerThread:10945 [handler.py:handle_request():144] handle_request: status_report
2023-03-01 17:28:46,890 DEBUG   HandlerThread:10945 [handler.py:handle_request():144] handle_request: keepalive
2023-03-01 17:28:50,940 DEBUG   HandlerThread:10945 [handler.py:handle_request():144] handle_request: status_report
2023-03-01 17:28:51,891 DEBUG   HandlerThread:10945 [handler.py:handle_request():144] handle_request: keepalive
2023-03-01 17:28:55,092 DEBUG   HandlerThread:10945 [handler.py:handle_request():144] handle_request: shutdown
2023-03-01 17:28:55,092 INFO    HandlerThread:10945 [handler.py:finish():841] shutting down handler
2023-03-01 17:28:55,231 INFO    WriterThread:10945 [datastore.py:close():299] close: /home/daniel/DARM/darm_mujoco/darm_training/wandb/run-20230301_170907-wf7bthr5/run-wf7bthr5.wandb
2023-03-01 17:28:55,941 DEBUG   HandlerThread:10945 [handler.py:handle_request():144] handle_request: status_report
2023-03-01 17:28:59,880 WARNING StreamThr :10945 [internal.py:is_dead():415] Internal process exiting, parent pid 10612 disappeared
2023-03-01 17:28:59,881 ERROR   StreamThr :10945 [internal.py:wandb_internal():153] Internal process shutdown.
2023-03-01 17:28:59,942 INFO    SenderThread:10945 [sender.py:finish():1493] shutting down sender
2023-03-01 17:28:59,943 INFO    SenderThread:10945 [dir_watcher.py:finish():362] shutting down directory watcher
2023-03-01 17:28:59,943 INFO    WriterThread:10945 [datastore.py:close():299] close: /home/daniel/DARM/darm_mujoco/darm_training/wandb/run-20230301_172826-4lvrnkpa/run-4lvrnkpa.wandb
2023-03-01 17:28:59,942 INFO    HandlerThread:10945 [handler.py:finish():841] shutting down handler
2023-03-01 17:29:00,941 INFO    SenderThread:10945 [dir_watcher.py:finish():392] scan: /home/daniel/DARM/darm_mujoco/darm_training/wandb/run-20230301_172826-4lvrnkpa/files
2023-03-01 17:29:00,942 INFO    SenderThread:10945 [dir_watcher.py:finish():406] scan save: /home/daniel/DARM/darm_mujoco/darm_training/wandb/run-20230301_172826-4lvrnkpa/files/config.yaml config.yaml
2023-03-01 17:29:00,943 INFO    SenderThread:10945 [file_pusher.py:finish():162] shutting down file pusher
2023-03-01 17:29:00,945 INFO    SenderThread:10945 [file_pusher.py:join():167] waiting for file pusher
2023-03-01 17:29:17,349 WARNING FileStreamThread:10945 [file_stream.py:request_with_retry():667] requests_with_retry encountered retryable exception: ('Connection aborted.', RemoteDisconnected('Remote end closed connection without response')). func: <bound method Session.post of <requests.sessions.Session object at 0x7fb4c8010130>>, args: ('https://api.wandb.ai/files/danieladejumo/DARM/4lvrnkpa/file_stream',), kwargs: {'json': {'complete': False, 'failed': False, 'dropped': 0, 'uploaded': []}}
2023-03-01 17:29:38,079 WARNING FileStreamThread:10945 [file_stream.py:request_with_retry():667] requests_with_retry encountered retryable exception: ('Connection aborted.', ConnectionResetError(104, 'Connection reset by peer')). func: <bound method Session.post of <requests.sessions.Session object at 0x7fb4c8010130>>, args: ('https://api.wandb.ai/files/danieladejumo/DARM/4lvrnkpa/file_stream',), kwargs: {'json': {'complete': False, 'failed': False, 'dropped': 0, 'uploaded': []}}
2023-03-01 17:29:47,256 INFO    wandb-upload_0:10945 [upload_job.py:push():138] Uploaded file /home/daniel/DARM/darm_mujoco/darm_training/wandb/run-20230301_172826-4lvrnkpa/files/config.yaml
